<?xml version="1.0" ?>
<robot name="mesr" xmlns:xacro="http://ros.org/wiki/xacro">
  <!-- Including common properties and gazebo definitions for the robot -->
  <xacro:include filename="$(find mesr_description)/urdf/common_properties.xacro"/>
  <xacro:include filename="$(find mesr_description)/urdf/mesr.gazebo.xacro"/>
  
  
  <!-- Base footprint of the robot -->
  <link name="base_footprint"/>

  <!-- Base joint that connects the base footprint and base link -->
  <joint name="base_joint" type="fixed">
    <parent link="base_footprint"/>
    <child link="base_link"/>
    <origin xyz="0.0 0.0 0.010" rpy="0 0 0"/>
  </joint>

  <!-- Base link that contains visual, collision and inertial properties -->
  <link name="base_link">
    <!-- Visual properties of the base link -->
    <visual>
      <origin xyz="0 0 0.02" rpy="0 0 0"/>
      <geometry>
        <mesh filename="package://kobuki_description/meshes/main_body.dae" scale="0.5 0.5 0.5"/>
      </geometry>
      <material name="light_black"/>
    </visual>

    <!-- Collision properties of the base link -->
    <collision>
      <origin xyz="-0.032 0 0.070" rpy="0 0 0"/>
      <geometry>
        <box size="0.140 0.140 0.143"/>
      </geometry>
    </collision>

    <!-- Inertial properties of the base link -->
    <inertial>
      <origin xyz="0 0 0" rpy="0 0 0"/>
      <mass value="8.2573504e-01"/>
      <inertia ixx="2.2124416e-03" ixy="-1.2294101e-05" ixz="3.4938785e-05"
               iyy="2.1193702e-03" iyz="-5.0120904e-06"
               izz="2.0064271e-03" />
    </inertial>
  </link>

  
  <!-- Enclosure joint and link start -->
  <!-- Enclosure joint that connects base link and enclosure -->
  <joint name="encl_joint" type="fixed">
    <parent link="base_link"/>
    <child link="enclosure"/>
    <origin xyz="0.0 0.0 0.0" rpy="0 0 1.5708"/>
 </joint>
 

  <link name="enclosure">
    <visual>
      <origin xyz="-0.0875 -0.123 -0.005" rpy="0 0 0"/>
      <geometry>
        <mesh filename="package://mesr_description/meshes/bases/full_rover_no_turtle2.STL" scale="0.5 0.5 0.5"/>
      </geometry>

     <material name="light_black">
     	<color rgba = "0.1 0.1 0.1 0.5"/>
     </material>

     <!--
     <material>Gazebo/GreyTransparent</material>
     -->
    </visual>

    
    
    <collision>
      <origin xyz="-0.0875 -0.123 -0.005" rpy="0 0 0"/>
      <geometry>
        <mesh filename="package://mesr_description/meshes/bases/full_rover_no_turtle2.STL" scale="0.5 0.5 0.5"/>
      </geometry>
    </collision>

    <inertial>
      <origin xyz="0 0 0" rpy="0 0 0"/>
      <mass value="8.2573504e-01"/>
      <inertia ixx="2.2124416e-03" ixy="-1.2294101e-05" ixz="3.4938785e-05"
               iyy="2.1193702e-03" iyz="-5.0120904e-06"
               izz="2.0064271e-03" />
    </inertial>
  </link>
  
  <!-- Enclosure test end -->

  <joint name="wheel_left_joint" type="continuous">
    <parent link="base_link"/>
    <child link="wheel_left_link"/>
    <origin xyz="0.0 0.08 0.023" rpy="-1.57 0 0"/>
    <axis xyz="0 0 1"/>
  </joint>

  <link name="wheel_left_link">
    <visual>
      <origin xyz="0 0.02 -0.02" rpy="1.57 0 0"/>
      <geometry>
        <mesh filename="package://mesr_description/meshes/wheels/left_tire.stl" scale="0.00038 0.00038 0.00038"/>
      </geometry>
      <material name="dark"/>
    </visual>

    <collision>
      <origin xyz="0 0 0" rpy="0 0 0"/>
      <geometry>
        <cylinder length="0.018" radius="0.033"/>
      </geometry>
    </collision>

<!--
    <inertial>
      <origin xyz="0 0 0" />
      <mass value="2.8498940e-02" />
      <inertia ixx="1.1175580e-05" ixy="-4.2369783e-11" ixz="-5.9381719e-09"
               iyy="1.1192413e-05" iyz="-1.4400107e-11"
               izz="2.0712558e-05" />
      </inertial>
 -->
 
 <inertial>
  <origin xyz="0 0 0" />
  <mass value="2.8498940e-02" />
  <inertia ixx="2.2351160e-05" ixy="-4.2369783e-11" ixz="-5.9381719e-09"
           iyy="2.2384826e-05" iyz="-1.4400107e-11"
           izz="4.1425116e-05" />
</inertial>

  </link>
  
  <gazebo reference="wheel_left_link">
  <material>
    <mu>30.0</mu>
    <mu2>30.0</mu2>
  </material>
</gazebo>


  <joint name="wheel_right_joint" type="continuous">
    <parent link="base_link"/>
    <child link="wheel_right_link"/>
    <origin xyz="0.0 -0.080 0.023" rpy="-1.57 0 0"/>
    <axis xyz="0 0 1"/>
  </joint>

  <link name="wheel_right_link">
    <visual>
      <origin xyz="0 0.02 0.02" rpy="1.57 0 0"/>
      <geometry>
        <mesh filename="package://mesr_description/meshes/wheels/right_tire.stl" scale="0.00038 0.00038 0.00038"/>
      </geometry>
      <material name="dark"/>
    </visual>

    <collision>
      <origin xyz="0 0 0" rpy="0 0 0"/>
      <geometry>
        <cylinder length="0.018" radius="0.033"/>
      </geometry>
    </collision>

<!--
    <inertial>
      <origin xyz="0 0 0" />
      <mass value="2.8498940e-02" />
      <inertia ixx="1.1175580e-05" ixy="-4.2369783e-11" ixz="-5.9381719e-09"
               iyy="1.1192413e-05" iyz="-1.4400107e-11"
               izz="2.0712558e-05" />
      </inertial>
 -->
 
 <inertial>
  <origin xyz="0 0 0" />
  <mass value="2.8498940e-02" />
  <inertia ixx="2.2351160e-05" ixy="-4.2369783e-11" ixz="-5.9381719e-09"
           iyy="2.2384826e-05" iyz="-1.4400107e-11"
           izz="4.1425116e-05" />
</inertial>

  </link>
  
  <gazebo reference="wheel_right_link">
  <material>
    <mu>30.0</mu>
    <mu2>30.0</mu2>
  </material>
</gazebo>


  <joint name="caster_back_joint" type="fixed">
    <parent link="base_link"/>
    <child link="caster_back_link"/>
    <origin xyz="-0.081 0 -0.004" rpy="-1.57 0 0"/>
  </joint>

  <link name="caster_back_link">
    <collision>
      <origin xyz="0 0.001 0" rpy="0 0 0"/>
      <geometry>
        <box size="0.030 0.009 0.020"/>
      </geometry>
    </collision>

    <inertial>
      <origin xyz="0 0 0" />
      <mass value="0.005" />
      <inertia ixx="0.001" ixy="0.0" ixz="0.0"
               iyy="0.001" iyz="0.0"
               izz="0.001" />
    </inertial>
  </link>

  <joint name="imu_joint" type="fixed">
    <parent link="base_link"/>
    <child link="imu_link"/>
    <origin xyz="-0.032 0 0.068" rpy="0 0 0"/>
  </joint>

  <link name="imu_link"/>

 
</robot>
