<?xml version="1.0" ?>
<robot name="mesr" xmlns:xacro="http://ros.org/wiki/xacro">
  <xacro:include filename="$(find mesr_description)/urdf/common_properties.xacro"/>
  <xacro:include filename="$(find mesr_description)/urdf/mesr.gazebo.xacro"/>
  
  

  <link name="base_footprint"/>

  <joint name="base_joint" type="fixed">
    <parent link="base_footprint"/>
    <child link="base_link"/>
    <origin xyz="0.0 0.0 0.020" rpy="0 0 0"/>
  </joint>

  <link name="base_link">
    <visual>
      <origin xyz="0 0 0.04" rpy="0 0 0"/>
      <geometry>
        <mesh filename="package://kobuki_description/meshes/main_body.dae" scale="1.0 1.0 1.0"/>
      </geometry>
      <material name="light_black"/>
    </visual>

    <collision>
      <origin xyz="-0.064 0 0.140" rpy="0 0 0"/>
      <geometry>
        <box size="0.0 0.0 0.0"/>
      </geometry>
    </collision>

    <inertial>
      <origin xyz="0 0 0" rpy="0 0 0"/>
      <mass value="8.2573504e-01"/>
      <inertia ixx="2.2124416e-03" ixy="-1.2294101e-05" ixz="3.4938785e-05"
               iyy="2.1193702e-03" iyz="-5.0120904e-06"
               izz="2.0064271e-03" />
    </inertial>
  </link>
  
    <!-- Enclosure test start -->
  
  
  <joint name="encl_joint" type="fixed">
    <parent link="base_link"/>
    <child link="enclosure"/>
    <origin xyz="0.0 0.0 0.0" rpy="0 0 1.5708"/>
 </joint>
 

  <link name="enclosure">
    <visual>
      <origin xyz="-0.1750 -0.246 -0.010" rpy="0 0 0"/>
      <geometry>
        <mesh filename="package://mesr_description/meshes/bases/sube_rover_enclosure.stl" scale="1.0 1.0 1.0"/>
      </geometry>

     <material name="light_black">
     	<color rgba = "0.1 0.1 0.1 1.0"/>
     </material>

     <!--
     <material>Gazebo/GreyTransparent</material>
     -->
    </visual>

    
    
    <collision>
      <origin xyz="-0.1750 -0.246 -0.010" rpy="0 0 0"/>
      <geometry>
        <mesh filename="package://mesr_description/meshes/bases/sube_rover_enclosure.stl" scale="1.0 1.0 1.0"/>
      </geometry>
    </collision>

    <inertial>
      <origin xyz="0 0 0" rpy="0 0 0"/>
      <mass value="0"/>
      <inertia ixx="0" ixy="0" ixz="0"
               iyy="0" iyz="0"
               izz="0" />
    </inertial>
  </link>
  
  <!-- Enclosure test end -->

  <joint name="wheel_left_joint" type="continuous">
    <parent link="base_link"/>
    <child link="wheel_left_link"/>
    <origin xyz="0.00 0.118 0.016" rpy="-1.57 0 0"/>
    <axis xyz="0 0 1"/>
  </joint>

  <link name="wheel_left_link">
    <visual>
      <origin xyz="0 0 0" rpy="0 0 0"/>
      <geometry>
        <mesh filename="package://mesr_description/meshes/wheels/t2_wheel.dae" scale="1.0 1.0 1.0"/>
      </geometry>
      <material name="dark"/>
    </visual>

    <collision>
      <origin xyz="0 0 0" rpy="0 0 0"/>
      <geometry>
        <cylinder length="0.0206" radius="0.0350"/>
      </geometry>
    </collision>

    <inertial>
      <origin xyz="0 0 0" />
      <mass value="0.01" />
      <inertia ixx="0.001" ixy="0.0" ixz="0.0"
               iyy="0.001" iyz="0.0"
               izz="0.001" />
    </inertial>

  </link>
  
  <gazebo reference="wheel_left_link">
  <material>
    <mu>30.0</mu>
    <mu2>30.0</mu2>
  </material>
</gazebo>


  <joint name="wheel_right_joint" type="continuous">
    <parent link="base_link"/>
    <child link="wheel_right_link"/>
    <origin xyz="0.00 -0.118 0.016" rpy="-1.57 0 0"/>
    <axis xyz="0 0 1"/>
  </joint>

  <link name="wheel_right_link">
    <visual>
      <origin xyz="0 0 0" rpy="0 0 0"/>
      <geometry>
        <mesh filename="package://mesr_description/meshes/wheels/t2_wheel.dae" scale="1.0 1.0 1.0"/>
      </geometry>
      <material name="dark"/>
    </visual>

    <collision>
      <origin xyz="0 0 0" rpy="0 0 0"/>
      <geometry>
        <cylinder length="0.0206" radius="0.0350"/>
      </geometry>
    </collision>
 
   <inertial>
      <origin xyz="0 0 0" />
      <mass value="0.01" />
      <inertia ixx="0.001" ixy="0.0" ixz="0.0"
               iyy="0.001" iyz="0.0"
               izz="0.001" />
    </inertial>

  </link>
  
  <gazebo reference="wheel_right_link">
  <material>
    <mu>30.0</mu>
    <mu2>30.0</mu2>
  </material>
</gazebo>


  <joint name="caster_back_joint" type="fixed">
    <parent link="base_link"/>
    <child link="caster_back_link"/>
    <origin xyz="-0.162 0 -0.008" rpy="-1.57 0 0"/>
  </joint>

  <link name="caster_back_link">
    <collision>
      <origin xyz="0 0.002 0" rpy="0 0 0"/>
      <geometry>
        <box size="0.060 0.018 0.040"/>
      </geometry>
    </collision>

    <inertial>
      <origin xyz="0 0 0" />
      <mass value="0.005" />
      <inertia ixx="0.001" ixy="0.0" ixz="0.0"
               iyy="0.001" iyz="0.0"
               izz="0.001" />
    </inertial>
  </link>

  <joint name="imu_joint" type="fixed">
    <parent link="base_link"/>
    <child link="imu_link"/>
    <origin xyz="-0.064 0 0.136" rpy="0 0 0"/>
  </joint>

  <link name="imu_link"/>

 
</robot>
